Workbook

Sheet OIC Function  List
I1: Phase1: Now~2022/12/31
B2: * Cowin MES(OIC) Function List (Scope定义) | I2: Phase2: 2023/1/1~2023/3/31
B3: Level 1 | C3: Level 2 | D3: NO | E3: Level 3 | F3: 模块 | G3: 重点关注 | H3: 功能确定 | I3: Phase | J3: 参考系统 | K3: 参考UI | L3: 有无 | M3: 接口 | U3: 界面说明 | V3: 功能构建 | Z3: 设计通过 | AA3: 设计评审计划 | AD3: 第一轮 | AN3: 第二轮 | AX3: 代码检查
M4: ERP | N4: EAP | O4: MCS | P4: RTD | Q4: RMS | R4: FDC | S4: R2R | T4: Fab | V4: 责任人 | W4: 开发人 | X4: 开发地 | Y4: 完成 | AA4: Plan | AB4: Act | AC4: 评审人员 | AD4: 测试完成 | AE4: 改善完成 | AF4: 测试通过 | AG4: 开发改善 Day | AH4: PlanStart | AI4: PlanEnd | AJ4: ActDays | AK4: ActStart | AL4: ActEnd | AM4: 开发者 | AN4: 测试完成 | AO4: 改善完成 | AP4: 测试通过 | AQ4: 开发改善 Day | AR4: PlanStart | AS4: PlanEnd | AT4: ActDays | AU4: ActStart | AV4: ActEnd | AW4: 开发者 | AX4: 检查人 | AY4: 检修计划 | AZ4: 完成
B5: Main | C5: Main | D5: =ROW()-4 -> 1 | E5: Main WIP（View Lot） | F5: Main | H5: 确定 | I5: Phase1 | J5: AMAT | K5: 主页 | L5: 有 | U5: 非 PHOTO, Sorter 机台的 Machine , Lot 监控及操作 | V5: 申克楠 | W5: 常刘勺 | X5: 苏州
B6: Carrier Mgt | D6: =ROW()-4 -> 2 | E6: Add Carrier Comment | F6: Carrier | G6: 非重点 | H6: 确定 | I6: Phase1 | J6: AMAT | K6: Add Carrier Comment | L6: 无 | U6: 添加Carrier Comment | V6: 杨金杰 | W6: 郭天娇 | X6: 无锡 | AA6: 44852 | AG6: 2 | AH6: =AA6+1 -> 44853 | AI6: =AH6+AG6 -> 44855
D7: =ROW()-4 -> 3 | E7: Cancel Clean | F7: Carrier | G7: 重点 | H7: 确定 | I7: Phase1 | J7: AMAT | L7: 无 | U7: Cancel Set Clean,Cancel Start Clean | V7: 杨金杰 | W7: 郭天娇 | X7: 无锡 | AA7: 44858 | AG7: 3 | AH7: =AI22+1 -> 44862 | AI7: =AH7+AG7 -> 44865
D8: =ROW()-4 -> 4 | E8: Cancel Inspection | F8: Carrier | G8: 重点 | H8: 确定 | I8: Phase1 | J8: AMAT | L8: 无 | U8: Cacel Set Inspetion | V8: 杨金杰 | W8: 郭天娇 | X8: 无锡 | AA8: 44872 | AG8: 3 | AH8: =AA8+1 -> 44873 | AI8: =AH8+AG8 -> 44876
D9: =ROW()-4 -> 5 | E9: Carrier Data Collection | F9: Carrier | J9: AMAT | L9: 无 | V9: 李彬
D10: =ROW()-4 -> 6 | E10: Disposal/Undo Disposal | F10: Carrier | G10: 次重点 | H10: 确定 | I10: Phase1 | J10: AMAT | L10: 无 | U10: Set Disposal之后的 处置,和Cancel 处置Carrier的动作 | V10: 杨金杰 | W10: 郭天娇 | X10: 无锡 | AA10: 44865 | AG10: 3 | AH10: =AA10+1 -> 44866 | AI10: =AH10+AG10 -> 44869
D11: =ROW()-4 -> 7 | E11: Inspection Flow Control | F11: Carrier | J11: AMAT | L11: 无 | V11: 杨金杰 | W11: 郭天娇 | X11: 无锡
D12: =ROW()-4 -> 8 | E12: Start/End Inspection | F12: Carrier | G12: 重点 | H12: 确定 | I12: Phase1 | J12: AMAT | L12: 无 | U12: 开始Carrier 量测，结束Carrier量测 | V12: 杨金杰 | W12: 郭天娇 | X12: 无锡 | AA12: 44872 | AG12: 3 | AH12: =AA12+1 -> 44873 | AI12: =AH12+AG12 -> 44876
D13: =ROW()-4 -> 9 | E13: Repair FOUP | F13: Carrier | G13: 次重点 | H13: 确定 | I13: Phase1 | J13: AMAT | L13: 无 | U13: 修理FOUP | V13: 杨金杰 | W13: 郭天娇 | X13: 无锡 | AA13: 44865 | AG13: 3 | AH13: =AA13+1 -> 44866 | AI13: =AH13+AG13 -> 44869
D14: =ROW()-4 -> 10 | E14: Reserve Target Carrier | F14: Carrier | G14: 重点 | H14: 确定 | I14: Phase1 | J14: AMAT | K14: Reserve Target Carrier | L14: 无 | U14: 预约Carrier,防止其他用途使用 | V14: 杨金杰 | W14: 郭天娇 | X14: 无锡 | Y14: 完成 | AG14: 3 | AH14: =AA14+1 -> 1 | AI14: =AH14+AG14 -> 4
D15: =ROW()-4 -> 11 | E15: Set Disposal/Cancel Disposal | F15: Carrier | G15: 次重点 | H15: 确定 | I15: Phase1 | J15: AMAT | L15: 无 | U15: Repair/Scrap之前的设定处置,和Cancel 设定 处置Carrier的动作 | V15: 杨金杰 | W15: 郭天娇 | X15: 无锡 | AA15: 44865 | AG15: 3 | AH15: =AA15+1 -> 44866 | AI15: =AH15+AG15 -> 44869
D16: =ROW()-4 -> 12 | E16: Set Clean | F16: Carrier | G16: 重点 | H16: 确定 | I16: Phase1 | J16: AMAT | L16: 无 | U16: 设定Clean | V16: 杨金杰 | W16: 郭天娇 | X16: 无锡 | AA16: 44858 | AG16: 3 | AH16: =AI7+1 -> 44866 | AI16: =AH16+AG16 -> 44869
D17: =ROW()-4 -> 13 | E17: Set Inspection | F17: Carrier | G17: 重点 | H17: 确定 | I17: Phase1 | J17: AMAT | L17: 无 | U17: 设定Carrier Inspecton | V17: 杨金杰 | W17: 郭天娇 | X17: 无锡 | AA17: 44872 | AG17: 3 | AH17: =AA17+1 -> 44873 | AI17: =AH17+AG17 -> 44876
D18: =ROW()-4 -> 14 | E18: Special Transfer Lot | F18: Carrier | J18: AMAT | L18: 无 | U18: 特殊Transfer Lot处理 | V18: 杨金杰 | W18: 郭天娇 | X18: 无锡
D19: =ROW()-4 -> 15 | E19: Start/End Clean | F19: Carrier | G19: 重点 | H19: 确定 | I19: Phase1 | J19: AMAT | L19: 无 | U19: 开始Carrier Clean,结束Carrier Clean | V19: 杨金杰 | W19: 郭天娇 | X19: 无锡 | AA19: 44858 | AG19: 3 | AH19: =AI16+1 -> 44870 | AI19: =AH19+AG19 -> 44873
D20: =ROW()-4 -> 16 | E20: Update Carrier Component | F20: Carrier | J20: AMAT | L20: 无 | U20: 更新Carrier组件(?) | V20: 杨金杰 | W20: 郭天娇 | X20: 无锡
C21: View Carrier Info | D21: =ROW()-4 -> 17 | E21: View Carrier Cleaning History | F21: Carrier | G21: 次重点 | H21: 确定 | I21: Phase1 | J21: AMAT | L21: 无 | U21: 查询Carrier Cleaning 历史记录 | V21: 杨金杰 | W21: 郭天娇 | X21: 无锡 | AA21: 44852 | AG21: 2 | AH21: =AI6+1 -> 44856 | AI21: =AH21+AG21 -> 44858
C22: View Carrier Info | D22: =ROW()-4 -> 18 | E22: View Carrier Cycle | F22: Carrier | G22: 次重点 | H22: 确定 | I22: Phase1 | J22: AMAT | L22: 无 | U22: 查询Carrie Cycle现况 | V22: 杨金杰 | W22: 郭天娇 | X22: 无锡 | AA22: 44852 | AG22: 2 | AH22: =AI21+1 -> 44859 | AI22: =AH22+AG22 -> 44861
B23: Eqp Mgt | D23: =ROW()-4 -> 19 | E23: Buffer Tool Physical Foup Maintain | F23: Machine | J23: AMAT | L23: 无 | U23: 管理Buffer的FOUP | V23: 杨金杰 | W23: 王哲 | X23: 无锡
C24: One Key Touch | D24: =ROW()-4 -> 20 | E24: Control Action History | F24: Machine | J24: AMAT | L24: 无 | V24: 杨金杰 | W24: 王哲 | X24: 无锡
D25: =ROW()-4 -> 21 | E25: Customize EQP Information | F25: Machine | J25: AMAT | L25: 无 | V25: 杨金杰 | W25: 王哲 | X25: 无锡
D26: =ROW()-4 -> 22 | E26: Delete Chamber Current Lots | F26: Machine | G26: 次重点 | H26: 确定 | I26: Phase1 | J26: AMAT | L26: 无 | U26: 删除掉chamber的Current Lot | V26: 杨金杰 | W26: 王哲 | X26: 无锡 | AA26: 44866 | AG26: 3 | AH26: =AA26+1 -> 44867 | AI26: =AH26+AG26 -> 44870
D27: =ROW()-4 -> 23 | E27: Equipment Couple Port | F27: Machine | G27: 重点 | H27: 确定 | I27: Phase1 | J27: AMAT | L27: 无 | U27: Machine Couple Port | V27: 杨金杰 | W27: 王哲 | X27: 无锡 | AA27: 44873 | AG27: 3 | AH27: =AA27+1 -> 44874 | AI27: =AH27+AG27 -> 44877
D28: =ROW()-4 -> 24 | E28: EQP Manual Process Configuration | F28: Machine | J28: AMAT | L28: 无 | V28: 杨金杰 | W28: 王哲 | X28: 无锡
D29: =ROW()-4 -> 25 | E29: MFG Eqp Security Control Maintenance | F29: Machine | J29: AMAT | L29: 无 | V29: 杨金杰 | W29: 王哲 | X29: 无锡
D30: =ROW()-4 -> 26 | E30: Modify Equipment Attribute | F30: Machine | G30: 重点 | H30: 确定 | I30: Phase1 | J30: AMAT | L30: 无 | U30: Modify机台属性 | V30: 杨金杰 | W30: 王哲 | X30: 无锡 | AA30: 44873 | AG30: 3 | AH30: =AA30+1 -> 44874 | AI30: =AH30+AG30 -> 44877
D31: =ROW()-4 -> 27 | E31: Modify Eqp Chamber Run Count | F31: Machine | G31: 次重点 | H31: 确定 | I31: Phase1 | J31: AMAT | L31: 无 | U31: Modify Chamber进行中的Lot | V31: 杨金杰 | W31: 王哲 | X31: 无锡 | AA31: 44866 | AG31: 3 | AH31: =AA31+1 -> 44867 | AI31: =AH31+AG31 -> 44870
D32: =ROW()-4 -> 28 | E32: Modify Equipment Current Lots | F32: Machine | G32: 次重点 | H32: 确定 | I32: Phase1 | J32: AMAT | L32: 无 | U32: Modify机台进行中的Lot | V32: 杨金杰 | W32: 王哲 | X32: 无锡 | AA32: 44866 | AG32: 3 | AH32: =AA32+1 -> 44867 | AI32: =AH32+AG32 -> 44870
D33: =ROW()-4 -> 29 | E33: Set Equipment Capability | F33: Machine | G33: 次重点 | H33: 确定 | I33: Phase1 | J33: AMAT | L33: 无 | U33: 设定机台的Capability | V33: 杨金杰 | W33: 王哲 | X33: 无锡 | AA33: 44859 | AG33: 3 | AH33: =AA33+1 -> 44860 | AI33: =AH33+AG33 -> 44863
C34: One Key Touch | D34: =ROW()-4 -> 30 | E34: One Key Touch | F34: Machine | J34: AMAT | L34: 无 | V34: 杨金杰 | W34: 王哲 | X34: 无锡
C35: One Key Touch | D35: =ROW()-4 -> 31 | E35: One Key Touch Detail History | F35: Machine | J35: AMAT | L35: 无 | V35: 杨金杰 | W35: 王哲 | X35: 无锡
C36: One Key Touch | D36: =ROW()-4 -> 32 | E36: Power Source Setup | F36: Machine | J36: AMAT | L36: 无 | V36: 杨金杰 | W36: 王哲 | X36: 无锡
C37: One Key Touch | D37: =ROW()-4 -> 33 | E37: Power Source Setup History | F37: Machine | J37: AMAT | L37: 无 | V37: 杨金杰 | W37: 王哲 | X37: 无锡
D38: =ROW()-4 -> 34 | E38: Reticle Equipment Process History | F38: Machine | G38: 次重点 | H38: 确定 | I38: Phase1 | J38: AMAT | L38: 无 | U38: Reticle Process机台的历史记录 | V38: 杨金杰 | W38: 王哲 | X38: 无锡 | AA38: 44859 | AG38: 3 | AH38: =AA38+1 -> 44860 | AI38: =AH38+AG38 -> 44863
D39: =ROW()-4 -> 35 | E39: Set Chamber Capability | F39: Machine | G39: 次重点 | H39: 确定 | I39: Phase1 | J39: AMAT | L39: 无 | U39: 设定Chamber的Capability | V39: 杨金杰 | W39: 王哲 | X39: 无锡 | AA39: 44859 | AG39: 3 | AH39: =AA39+1 -> 44860 | AI39: =AH39+AG39 -> 44863
C40: Tank Control | D40: =ROW()-4 -> 36 | E40: Tank Count Info | F40: Machine | I40: Phase2 | J40: AMAT | L40: 无 | V40: 杨金杰 | W40: 王哲 | X40: 无锡
...

Sheet Summary
B2: * cvMES Function List R&D Status(对比 300Works Basic Function)
B3: Type | C3: 300Works(Basic) | D3: B2 Funcation(Basic) | E3: 完成 | F3: 完成率
F4: 对比300works | G4: 对比B2 | H4: 完成 | I4: 设计中 | J4: 开发中 | K4: 测试中 | L4: 未推进 | M4: 待确认
B5: Carrier | C5: =SUMIF('cvMES Function List 定义'!$K:$K,$B5,'cvMES Function List 定义'!$B:$B) -> 29 | D5: =SUMIF('cvMES Function List 定义'!$K:$K,$B5,'cvMES Function List 定义'!$C:$C) -> 0 | E5: =COUNTIFS('cvMES Function List 定义'!$K:$K,$B5,'cvMES Function List 定义'!L:L,$H$4) -> 18 | F5: =IF(ISERROR(E5/C5),"",E5/C5) -> 0.62068966 | G5: =E5/D5 -> #DIV/0! | H5: =SUMIFS('cvMES Function List 定义'!$D:$D,'cvMES Function List 定义'!$K:$K,$B5,'cvMES Function List 定义'!$L:$L,H$4) -> 18 | I5: =SUMIFS('cvMES Function List 定义'!$D:$D,'cvMES Function List 定义'!$K:$K,$B5,'cvMES Function List 定义'!$L:$L,I$4) -> 1 | J5: =SUMIFS('cvMES Function List 定义'!$D:$D,'cvMES Function List 定义'!$K:$K,$B5,'cvMES Function List 定义'!$L:$L,J$4) -> 1 | K5: =SUMIFS('cvMES Function List 定义'!$D:$D,'cvMES Function List 定义'!$K:$K,$B5,'cvMES Function List 定义'!$L:$L,K$4) -> 0 | L5: =SUMIFS('cvMES Function List 定义'!$D:$D,'cvMES Function List 定义'!$K:$K,$B5,'cvMES Function List 定义'!$L:$L,L$4) -> 0 | M5: =SUMIFS('cvMES Function List 定义'!$D:$D,'cvMES Function List 定义'!$K:$K,$B5,'cvMES Function List 定义'!$L:$L,M$4) -> 3
B6: Machine | C6: =SUMIF('cvMES Function List 定义'!$K:$K,$B6,'cvMES Function List 定义'!$B:$B) -> 37 | D6: =SUMIF('cvMES Function List 定义'!$K:$K,$B6,'cvMES Function List 定义'!$C:$C) -> 0 | E6: =COUNTIFS('cvMES Function List 定义'!$K:$K,$B6,'cvMES Function List 定义'!L:L,$H$4) -> 12 | F6: =IF(ISERROR(E6/C6),"",E6/C6) -> 0.32432432 | G6: =E6/D6 -> #DIV/0! | H6: =SUMIFS('cvMES Function List 定义'!$D:$D,'cvMES Function List 定义'!$K:$K,$B6,'cvMES Function List 定义'!$L:$L,H$4) -> 12 | I6: =SUMIFS('cvMES Function List 定义'!$D:$D,'cvMES Function List 定义'!$K:$K,$B6,'cvMES Function List 定义'!$L:$L,I$4) -> 0 | J6: =SUMIFS('cvMES Function List 定义'!$D:$D,'cvMES Function List 定义'!$K:$K,$B6,'cvMES Function List 定义'!$L:$L,J$4) -> 0 | K6: =SUMIFS('cvMES Function List 定义'!$D:$D,'cvMES Function List 定义'!$K:$K,$B6,'cvMES Function List 定义'!$L:$L,K$4) -> 0 | L6: =SUMIFS('cvMES Function List 定义'!$D:$D,'cvMES Function List 定义'!$K:$K,$B6,'cvMES Function List 定义'!$L:$L,L$4) -> 0 | M6: =SUMIFS('cvMES Function List 定义'!$D:$D,'cvMES Function List 定义'!$K:$K,$B6,'cvMES Function List 定义'!$L:$L,M$4) -> 0
B7: Lot | C7: =SUMIF('cvMES Function List 定义'!$K:$K,$B7,'cvMES Function List 定义'!$B:$B) -> 105 | D7: =SUMIF('cvMES Function List 定义'!$K:$K,$B7,'cvMES Function List 定义'!$C:$C) -> 0 | E7: =COUNTIFS('cvMES Function List 定义'!$K:$K,$B7,'cvMES Function List 定义'!L:L,$H$4) -> 80 | F7: =IF(ISERROR(E7/C7),"",E7/C7) -> 0.76190476 | G7: =E7/D7 -> #DIV/0! | H7: =SUMIFS('cvMES Function List 定义'!$D:$D,'cvMES Function List 定义'!$K:$K,$B7,'cvMES Function List 定义'!$L:$L,H$4) -> 78 | I7: =SUMIFS('cvMES Function List 定义'!$D:$D,'cvMES Function List 定义'!$K:$K,$B7,'cvMES Function List 定义'!$L:$L,I$4) -> 0 | J7: =SUMIFS('cvMES Function List 定义'!$D:$D,'cvMES Function List 定义'!$K:$K,$B7,'cvMES Function List 定义'!$L:$L,J$4) -> 0 | K7: =SUMIFS('cvMES Function List 定义'!$D:$D,'cvMES Function List 定义'!$K:$K,$B7,'cvMES Function List 定义'!$L:$L,K$4) -> 0 | L7: =SUMIFS('cvMES Function List 定义'!$D:$D,'cvMES Function List 定义'!$K:$K,$B7,'cvMES Function List 定义'!$L:$L,L$4) -> 0 | M7: =SUMIFS('cvMES Function List 定义'!$D:$D,'cvMES Function List 定义'!$K:$K,$B7,'cvMES Function List 定义'!$L:$L,M$4) -> 2
B8: Inventory | C8: =SUMIF('cvMES Function List 定义'!$K:$K,$B8,'cvMES Function List 定义'!$B:$B) -> 10 | D8: =SUMIF('cvMES Function List 定义'!$K:$K,$B8,'cvMES Function List 定义'!$C:$C) -> 0 | E8: =COUNTIFS('cvMES Function List 定义'!$K:$K,$B8,'cvMES Function List 定义'!L:L,$H$4) -> 10 | F8: =IF(ISERROR(E8/C8),"",E8/C8) -> 1 | G8: =E8/D8 -> #DIV/0! | H8: =SUMIFS('cvMES Function List 定义'!$D:$D,'cvMES Function List 定义'!$K:$K,$B8,'cvMES Function List 定义'!$L:$L,H$4) -> 10 | I8: =SUMIFS('cvMES Function List 定义'!$D:$D,'cvMES Function List 定义'!$K:$K,$B8,'cvMES Function List 定义'!$L:$L,I$4) -> 0 | J8: =SUMIFS('cvMES Function List 定义'!$D:$D,'cvMES Function List 定义'!$K:$K,$B8,'cvMES Function List 定义'!$L:$L,J$4) -> 0 | K8: =SUMIFS('cvMES Function List 定义'!$D:$D,'cvMES Function List 定义'!$K:$K,$B8,'cvMES Function List 定义'!$L:$L,K$4) -> 0 | L8: =SUMIFS('cvMES Function List 定义'!$D:$D,'cvMES Function List 定义'!$K:$K,$B8,'cvMES Function List 定义'!$L:$L,L$4) -> 0 | M8: =SUMIFS('cvMES Function List 定义'!$D:$D,'cvMES Function List 定义'!$K:$K,$B8,'cvMES Function List 定义'!$L:$L,M$4) -> 0
B9: WIP | C9: =SUMIF('cvMES Function List 定义'!$K:$K,$B9,'cvMES Function List 定义'!$B:$B) -> 66 | D9: =SUMIF('cvMES Function List 定义'!$K:$K,$B9,'cvMES Function List 定义'!$C:$C) -> 0 | E9: =COUNTIFS('cvMES Function List 定义'!$K:$K,$B9,'cvMES Function List 定义'!L:L,$H$4) -> 59 | F9: =IF(ISERROR(E9/C9),"",E9/C9) -> 0.89393939 | G9: =E9/D9 -> #DIV/0! | H9: =SUMIFS('cvMES Function List 定义'!$D:$D,'cvMES Function List 定义'!$K:$K,$B9,'cvMES Function List 定义'!$L:$L,H$4) -> 52 | I9: =SUMIFS('cvMES Function List 定义'!$D:$D,'cvMES Function List 定义'!$K:$K,$B9,'cvMES Function List 定义'!$L:$L,I$4) -> 0 | J9: =SUMIFS('cvMES Function List 定义'!$D:$D,'cvMES Function List 定义'!$K:$K,$B9,'cvMES Function List 定义'!$L:$L,J$4) -> 2 | K9: =SUMIFS('cvMES Function List 定义'!$D:$D,'cvMES Function List 定义'!$K:$K,$B9,'cvMES Function List 定义'!$L:$L,K$4) -> 0 | L9: =SUMIFS('cvMES Function List 定义'!$D:$D,'cvMES Function List 定义'!$K:$K,$B9,'cvMES Function List 定义'!$L:$L,L$4) -> 1 | M9: =SUMIFS('cvMES Function List 定义'!$D:$D,'cvMES Function List 定义'!$K:$K,$B9,'cvMES Function List 定义'!$L:$L,M$4) -> 1
B10: CSN | C10: =SUMIF('cvMES Function List 定义'!$K:$K,$B10,'cvMES Function List 定义'!$B:$B) -> 6 | D10: 3 | E10: =COUNTIFS('cvMES Function List 定义'!$K:$K,$B10,'cvMES Function List 定义'!L:L,$H$4) -> 3 | F10: =IF(ISERROR(E10/C10),"",E10/C10) -> 0.5 | G10: =E10/D10 -> 1 | H10: =SUMIFS('cvMES Function List 定义'!$D:$D,'cvMES Function List 定义'!$K:$K,$B10,'cvMES Function List 定义'!$L:$L,H$4) -> 3 | I10: =SUMIFS('cvMES Function List 定义'!$D:$D,'cvMES Function List 定义'!$K:$K,$B10,'cvMES Function List 定义'!$L:$L,I$4) -> 0 | J10: =SUMIFS('cvMES Function List 定义'!$D:$D,'cvMES Function List 定义'!$K:$K,$B10,'cvMES Function List 定义'!$L:$L,J$4) -> 0 | K10: =SUMIFS('cvMES Function List 定义'!$D:$D,'cvMES Function List 定义'!$K:$K,$B10,'cvMES Function List 定义'!$L:$L,K$4) -> 0 | L10: =SUMIFS('cvMES Function List 定义'!$D:$D,'cvMES Function List 定义'!$K:$K,$B10,'cvMES Function List 定义'!$L:$L,L$4) -> 0 | M10: =SUMIFS('cvMES Function List 定义'!$D:$D,'cvMES Function List 定义'!$K:$K,$B10,'cvMES Function List 定义'!$L:$L,M$4) -> 0
B11: Test Wafer | C11: =SUMIF('cvMES Function List 定义'!$K:$K,$B11,'cvMES Function List 定义'!$B:$B) -> 23 | D11: =SUMIF('cvMES Function List 定义'!$K:$K,$B11,'cvMES Function List 定义'!$C:$C) -> 0 | E11: =COUNTIFS('cvMES Function List 定义'!$K:$K,$B11,'cvMES Function List 定义'!L:L,$H$4) -> 23 | F11: =IF(ISERROR(E11/C11),"",E11/C11) -> 1 | G11: =E11/D11 -> #DIV/0! | H11: =SUMIFS('cvMES Function List 定义'!$D:$D,'cvMES Function List 定义'!$K:$K,$B11,'cvMES Function List 定义'!$L:$L,H$4) -> 23 | I11: =SUMIFS('cvMES Function List 定义'!$D:$D,'cvMES Function List 定义'!$K:$K,$B11,'cvMES Function List 定义'!$L:$L,I$4) -> 0 | J11: =SUMIFS('cvMES Function List 定义'!$D:$D,'cvMES Function List 定义'!$K:$K,$B11,'cvMES Function List 定义'!$L:$L,J$4) -> 0 | K11: =SUMIFS('cvMES Function List 定义'!$D:$D,'cvMES Function List 定义'!$K:$K,$B11,'cvMES Function List 定义'!$L:$L,K$4) -> 0 | L11: =SUMIFS('cvMES Function List 定义'!$D:$D,'cvMES Function List 定义'!$K:$K,$B11,'cvMES Function List 定义'!$L:$L,L$4) -> 0 | M11: =SUMIFS('cvMES Function List 定义'!$D:$D,'cvMES Function List 定义'!$K:$K,$B11,'cvMES Function List 定义'!$L:$L,M$4) -> 0
B12: Reticle | C12: =SUMIF('cvMES Function List 定义'!$K:$K,$B12,'cvMES Function List 定义'!$B:$B) -> 63 | D12: =SUMIF('cvMES Function List 定义'!$K:$K,$B12,'cvMES Function List 定义'!$C:$C) -> 0 | E12: =COUNTIFS('cvMES Function List 定义'!$K:$K,$B12,'cvMES Function List 定义'!L:L,$H$4) -> 30 | F12: =IF(ISERROR(E12/C12),"",E12/C12) -> 0.47619048 | G12: =E12/D12 -> #DIV/0! | H12: =SUMIFS('cvMES Function List 定义'!$D:$D,'cvMES Function List 定义'!$K:$K,$B12,'cvMES Function List 定义'!$L:$L,H$4) -> 30 | I12: =SUMIFS('cvMES Function List 定义'!$D:$D,'cvMES Function List 定义'!$K:$K,$B12,'cvMES Function List 定义'!$L:$L,I$4) -> 0 | J12: =SUMIFS('cvMES Function List 定义'!$D:$D,'cvMES Function List 定义'!$K:$K,$B12,'cvMES Function List 定义'!$L:$L,J$4) -> 0 | K12: =SUMIFS('cvMES Function List 定义'!$D:$D,'cvMES Function List 定义'!$K:$K,$B12,'cvMES Function List 定义'!$L:$L,K$4) -> 0 | L12: =SUMIFS('cvMES Function List 定义'!$D:$D,'cvMES Function List 定义'!$K:$K,$B12,'cvMES Function List 定义'!$L:$L,L$4) -> 0 | M12: =SUMIFS('cvMES Function List 定义'!$D:$D,'cvMES Function List 定义'!$K:$K,$B12,'cvMES Function List 定义'!$L:$L,M$4) -> 2
B13: Sampling | C13: =SUMIF('cvMES Function List 定义'!$K:$K,$B13,'cvMES Function List 定义'!$B:$B) -> 16 | D13: =SUMIF('cvMES Function List 定义'!$K:$K,$B13,'cvMES Function List 定义'!$C:$C) -> 0 | E13: =COUNTIFS('cvMES Function List 定义'!$K:$K,$B13,'cvMES Function List 定义'!L:L,$H$4) -> 10 | F13: =IF(ISERROR(E13/C13),"",E13/C13) -> 0.625 | G13: =E13/D13 -> #DIV/0! | H13: =SUMIFS('cvMES Function List 定义'!$D:$D,'cvMES Function List 定义'!$K:$K,$B13,'cvMES Function List 定义'!$L:$L,H$4) -> 10 | I13: =SUMIFS('cvMES Function List 定义'!$D:$D,'cvMES Function List 定义'!$K:$K,$B13,'cvMES Function List 定义'!$L:$L,I$4) -> 0 | J13: =SUMIFS('cvMES Function List 定义'!$D:$D,'cvMES Function List 定义'!$K:$K,$B13,'cvMES Function List 定义'!$L:$L,J$4) -> 0 | K13: =SUMIFS('cvMES Function List 定义'!$D:$D,'cvMES Function List 定义'!$K:$K,$B13,'cvMES Function List 定义'!$L:$L,K$4) -> 2 | L13: =SUMIFS('cvMES Function List 定义'!$D:$D,'cvMES Function List 定义'!$K:$K,$B13,'cvMES Function List 定义'!$L:$L,L$4) -> 0 | M13: =SUMIFS('cvMES Function List 定义'!$D:$D,'cvMES Function List 定义'!$K:$K,$B13,'cvMES Function List 定义'!$L:$L,M$4) -> 0
B14: Phase1 | C14: =SUM(C5:C13) -> 355 | D14: =SUM(D5:D13) -> 3 | E14: =SUM(E5:E13) -> 245 | F14: =IF(ISERROR(E14/C14),"",E14/C14) -> 0.69014085 | G14: =E14/D14 -> 81.666667 | H14: =SUM(H5:H13) -> 236 | I14: =SUM(I5:I13) -> 1 | J14: =SUM(J5:J13) -> 3 | K14: =SUM(K5:K13) -> 2 | L14: =SUM(L5:L13) -> 1 | M14: =SUM(M5:M13) -> 8
B15: OCAP | C15: =SUMIF('cvMES Function List 定义'!$K:$K,$B15,'cvMES Function List 定义'!$B:$B) -> 2 | D15: =SUMIF('cvMES Function List 定义'!$K:$K,$B15,'cvMES Function List 定义'!$C:$C) -> 0 | E15: =COUNTIFS('cvMES Function List 定义'!$K:$K,$B15,'cvMES Function List 定义'!L:L,$H$4) -> 1 | F15: =IF(ISERROR(E15/C15),"",E15/C15) -> 0.5 | G15: =E15/D15 -> #DIV/0! | H15: =SUMIFS('cvMES Function List 定义'!$D:$D,'cvMES Function List 定义'!$K:$K,$B15,'cvMES Function List 定义'!$L:$L,H$4) -> 0 | I15: =SUMIFS('cvMES Function List 定义'!$D:$D,'cvMES Function List 定义'!$K:$K,$B15,'cvMES Function List 定义'!$L:$L,I$4) -> 0 | J15: =SUMIFS('cvMES Function List 定义'!$D:$D,'cvMES Function List 定义'!$K:$K,$B15,'cvMES Function List 定义'!$L:$L,J$4) -> 0 | K15: =SUMIFS('cvMES Function List 定义'!$D:$D,'cvMES Function List 定义'!$K:$K,$B15,'cvMES Function List 定义'!$L:$L,K$4) -> 0 | L15: =SUMIFS('cvMES Function List 定义'!$D:$D,'cvMES Function List 定义'!$K:$K,$B15,'cvMES Function List 定义'!$L:$L,L$4) -> 0 | M15: =SUMIFS('cvMES Function List 定义'!$D:$D,'cvMES Function List 定义'!$K:$K,$B15,'cvMES Function List 定义'!$L:$L,M$4) -> 0
B16: PCMS | C16: =SUMIF('cvMES Function List 定义'!$K:$K,$B16,'cvMES Function List 定义'!$B:$B) -> 36 | D16: =SUMIF('cvMES Function List 定义'!$K:$K,$B16,'cvMES Function List 定义'!$C:$C) -> 0 | E16: =COUNTIFS('cvMES Function List 定义'!$K:$K,$B16,'cvMES Function List 定义'!L:L,$H$4) -> 0 | F16: =IF(ISERROR(E16/C16),"",E16/C16) -> 0 | G16: =E16/D16 -> #DIV/0! | H16: =SUMIFS('cvMES Function List 定义'!$D:$D,'cvMES Function List 定义'!$K:$K,$B16,'cvMES Function List 定义'!$L:$L,H$4) -> 0 | I16: =SUMIFS('cvMES Function List 定义'!$D:$D,'cvMES Function List 定义'!$K:$K,$B16,'cvMES Function List 定义'!$L:$L,I$4) -> 0 | J16: =SUMIFS('cvMES Function List 定义'!$D:$D,'cvMES Function List 定义'!$K:$K,$B16,'cvMES Function List 定义'!$L:$L,J$4) -> 0 | K16: =SUMIFS('cvMES Function List 定义'!$D:$D,'cvMES Function List 定义'!$K:$K,$B16,'cvMES Function List 定义'!$L:$L,K$4) -> 0 | L16: =SUMIFS('cvMES Function List 定义'!$D:$D,'cvMES Function List 定义'!$K:$K,$B16,'cvMES Function List 定义'!$L:$L,L$4) -> 0 | M16: =SUMIFS('cvMES Function List 定义'!$D:$D,'cvMES Function List 定义'!$K:$K,$B16,'cvMES Function List 定义'!$L:$L,M$4) -> 0
B17: PRMS | C17: =SUMIF('cvMES Function List 定义'!$K:$K,$B17,'cvMES Function List 定义'!$B:$B) -> 12 | D17: =SUMIF('cvMES Function List 定义'!$K:$K,$B17,'cvMES Function List 定义'!$C:$C) -> 0 | E17: =COUNTIFS('cvMES Function List 定义'!$K:$K,$B17,'cvMES Function List 定义'!L:L,$H$4) -> 0 | F17: =IF(ISERROR(E17/C17),"",E17/C17) -> 0 | G17: =E17/D17 -> #DIV/0! | H17: =SUMIFS('cvMES Function List 定义'!$D:$D,'cvMES Function List 定义'!$K:$K,$B17,'cvMES Function List 定义'!$L:$L,H$4) -> 0 | I17: =SUMIFS('cvMES Function List 定义'!$D:$D,'cvMES Function List 定义'!$K:$K,$B17,'cvMES Function List 定义'!$L:$L,I$4) -> 0 | J17: =SUMIFS('cvMES Function List 定义'!$D:$D,'cvMES Function List 定义'!$K:$K,$B17,'cvMES Function List 定义'!$L:$L,J$4) -> 0 | K17: =SUMIFS('cvMES Function List 定义'!$D:$D,'cvMES Function List 定义'!$K:$K,$B17,'cvMES Function List 定义'!$L:$L,K$4) -> 0 | L17: =SUMIFS('cvMES Function List 定义'!$D:$D,'cvMES Function List 定义'!$K:$K,$B17,'cvMES Function List 定义'!$L:$L,L$4) -> 0 | M17: =SUMIFS('cvMES Function List 定义'!$D:$D,'cvMES Function List 定义'!$K:$K,$B17,'cvMES Function List 定义'!$L:$L,M$4) -> 0
B18: PTMS | C18: =SUMIF('cvMES Function List 定义'!$K:$K,$B18,'cvMES Function List 定义'!$B:$B) -> 10 | D18: =SUMIF('cvMES Function List 定义'!$K:$K,$B18,'cvMES Function List 定义'!$C:$C) -> 0 | E18: =COUNTIFS('cvMES Function List 定义'!$K:$K,$B18,'cvMES Function List 定义'!L:L,$H$4) -> 0 | F18: =IF(ISERROR(E18/C18),"",E18/C18) -> 0 | G18: =E18/D18 -> #DIV/0! | H18: =SUMIFS('cvMES Function List 定义'!$D:$D,'cvMES Function List 定义'!$K:$K,$B18,'cvMES Function List 定义'!$L:$L,H$4) -> 0 | I18: =SUMIFS('cvMES Function List 定义'!$D:$D,'cvMES Function List 定义'!$K:$K,$B18,'cvMES Function List 定义'!$L:$L,I$4) -> 0 | J18: =SUMIFS('cvMES Function List 定义'!$D:$D,'cvMES Function List 定义'!$K:$K,$B18,'cvMES Function List 定义'!$L:$L,J$4) -> 0 | K18: =SUMIFS('cvMES Function List 定义'!$D:$D,'cvMES Function List 定义'!$K:$K,$B18,'cvMES Function List 定义'!$L:$L,K$4) -> 0 | L18: =SUMIFS('cvMES Function List 定义'!$D:$D,'cvMES Function List 定义'!$K:$K,$B18,'cvMES Function List 定义'!$L:$L,L$4) -> 0 | M18: =SUMIFS('cvMES Function List 定义'!$D:$D,'cvMES Function List 定义'!$K:$K,$B18,'cvMES Function List 定义'!$L:$L,M$4) -> 0
B19: RTD | C19: =SUMIF('cvMES Function List 定义'!$K:$K,$B19,'cvMES Function List 定义'!$B:$B) -> 1 | D19: =SUMIF('cvMES Function List 定义'!$K:$K,$B19,'cvMES Function List 定义'!$C:$C) -> 0 | E19: =COUNTIFS('cvMES Function List 定义'!$K:$K,$B19,'cvMES Function List 定义'!L:L,$H$4) -> 0 | F19: =IF(ISERROR(E19/C19),"",E19/C19) -> 0 | G19: =E19/D19 -> #DIV/0! | H19: =SUMIFS('cvMES Function List 定义'!$D:$D,'cvMES Function List 定义'!$K:$K,$B19,'cvMES Function List 定义'!$L:$L,H$4) -> 0 | I19: =SUMIFS('cvMES Function List 定义'!$D:$D,'cvMES Function List 定义'!$K:$K,$B19,'cvMES Function List 定义'!$L:$L,I$4) -> 0 | J19: =SUMIFS('cvMES Function List 定义'!$D:$D,'cvMES Function List 定义'!$K:$K,$B19,'cvMES Function List 定义'!$L:$L,J$4) -> 0 | K19: =SUMIFS('cvMES Function List 定义'!$D:$D,'cvMES Function List 定义'!$K:$K,$B19,'cvMES Function List 定义'!$L:$L,K$4) -> 0 | L19: =SUMIFS('cvMES Function List 定义'!$D:$D,'cvMES Function List 定义'!$K:$K,$B19,'cvMES Function List 定义'!$L:$L,L$4) -> 0 | M19: =SUMIFS('cvMES Function List 定义'!$D:$D,'cvMES Function List 定义'!$K:$K,$B19,'cvMES Function List 定义'!$L:$L,M$4) -> 0
B20: Transportation | C20: =SUMIF('cvMES Function List 定义'!$K:$K,$B20,'cvMES Function List 定义'!$B:$B) -> 11 | D20: =SUMIF('cvMES Function List 定义'!$K:$K,$B20,'cvMES Function List 定义'!$C:$C) -> 0 | E20: =COUNTIFS('cvMES Function List 定义'!$K:$K,$B20,'cvMES Function List 定义'!L:L,$H$4) -> 0 | F20: =IF(ISERROR(E20/C20),"",E20/C20) -> 0 | G20: =E20/D20 -> #DIV/0! | H20: =SUMIFS('cvMES Function List 定义'!$D:$D,'cvMES Function List 定义'!$K:$K,$B20,'cvMES Function List 定义'!$L:$L,H$4) -> 0 | I20: =SUMIFS('cvMES Function List 定义'!$D:$D,'cvMES Function List 定义'!$K:$K,$B20,'cvMES Function List 定义'!$L:$L,I$4) -> 0 | J20: =SUMIFS('cvMES Function List 定义'!$D:$D,'cvMES Function List 定义'!$K:$K,$B20,'cvMES Function List 定义'!$L:$L,J$4) -> 0 | K20: =SUMIFS('cvMES Function List 定义'!$D:$D,'cvMES Function List 定义'!$K:$K,$B20,'cvMES Function List 定义'!$L:$L,K$4) -> 0 | L20: =SUMIFS('cvMES Function List 定义'!$D:$D,'cvMES Function List 定义'!$K:$K,$B20,'cvMES Function List 定义'!$L:$L,L$4) -> 0 | M20: =SUMIFS('cvMES Function List 定义'!$D:$D,'cvMES Function List 定义'!$K:$K,$B20,'cvMES Function List 定义'!$L:$L,M$4) -> 0
B21: WAT | C21: =SUMIF('cvMES Function List 定义'!$K:$K,$B21,'cvMES Function List 定义'!$B:$B) -> 12 | D21: =SUMIF('cvMES Function List 定义'!$K:$K,$B21,'cvMES Function List 定义'!$C:$C) -> 0 | E21: =COUNTIFS('cvMES Function List 定义'!$K:$K,$B21,'cvMES Function List 定义'!L:L,$H$4) -> 0 | F21: =IF(ISERROR(E21/C21),"",E21/C21) -> 0 | G21: =E21/D21 -> #DIV/0! | H21: =SUMIFS('cvMES Function List 定义'!$D:$D,'cvMES Function List 定义'!$K:$K,$B21,'cvMES Function List 定义'!$L:$L,H$4) -> 0 | I21: =SUMIFS('cvMES Function List 定义'!$D:$D,'cvMES Function List 定义'!$K:$K,$B21,'cvMES Function List 定义'!$L:$L,I$4) -> 0 | J21: =SUMIFS('cvMES Function List 定义'!$D:$D,'cvMES Function List 定义'!$K:$K,$B21,'cvMES Function List 定义'!$L:$L,J$4) -> 0 | K21: =SUMIFS('cvMES Function List 定义'!$D:$D,'cvMES Function List 定义'!$K:$K,$B21,'cvMES Function List 定义'!$L:$L,K$4) -> 0 | L21: =SUMIFS('cvMES Function List 定义'!$D:$D,'cvMES Function List 定义'!$K:$K,$B21,'cvMES Function List 定义'!$L:$L,L$4) -> 0 | M21: =SUMIFS('cvMES Function List 定义'!$D:$D,'cvMES Function List 定义'!$K:$K,$B21,'cvMES Function List 定义'!$L:$L,M$4) -> 0
B22: Phase2 | C22: =SUM(C15:C21) -> 84 | D22: =SUM(D15:D21) -> 0 | E22: =SUM(E15:E21) -> 1 | F22: =IF(ISERROR(E22/C22),"",E22/C22) -> 0.011904762 | G22: =E22/D22 -> #DIV/0! | H22: =SUM(H15:H21) -> 0 | I22: =SUM(I15:I21) -> 0 | J22: =SUM(J15:J21) -> 0 | K22: =SUM(K15:K21) -> 0 | L22: =SUM(L15:L21) -> 0 | M22: =SUM(M15:M21) -> 0
B23: Total | C23: =C14+C22 -> 439 | D23: =D14+D22 -> 3 | E23: =E14+E22 -> 246 | F23: =IF(ISERROR(E23/C23),"",E23/C23) -> 0.56036446 | G23: =E23/D23 -> 82 | H23: =H14+H22 -> 236 | I23: =I14+I22 -> 1 | J23: =J14+J22 -> 3 | K23: =K14+K22 -> 2 | L23: =L14+L22 -> 1 | M23: =M14+M22 -> 8

Sheet cvMES Function List 定义
E2: * Cpwin（MES）Function List
E3: Level1 | F3: Level2 | G3: No. | H3: 300Works(Basic) | I3: B2 Funcation | J3: cvMES | K3: 模块 | L3: 功能确认 | M3: 开发阶段 | N3: 界面说明 | O3: 责任人 | P3: 开发地 | Q3: 开发人 | R3: 交期 | S3: 实绩 | T3: 完成 | U3: Remark
A4: =B4&D4 -> 11 | B4: =IF(H4="","",1) -> 1 | C4: =IF(I4="","",1) | D4: =IF(J4="","",1) -> 1 | E4: Carrier Mgt | G4: 1 | H4: Add Carrier Comment | I4: =IF(ISERROR(VLOOKUP(H4,#REF!,9,0)),"",VLOOKUP(H4,#REF!,9,0)) | J4: Add Carrier Comment | K4: Carrier | L4: 设计中 | M4: 2022 | N4: 添加Carrier Comment | O4: 杨金杰
A5: =B5&D5 -> 11 | B5: =IF(H5="","",1) -> 1 | C5: =IF(I5="","",1) | D5: =IF(J5="","",1) -> 1 | G5: 2 | H5: Assign Carrier | I5: =IF(ISERROR(VLOOKUP(H5,#REF!,9,0)),"",VLOOKUP(H5,#REF!,9,0)) | J5: Assign Carrier | K5: Carrier | L5: 完成 | M5: 2022 | N5: Lot&Carrier逻辑 Match | O5: 杨金杰
A6: =B6&D6 -> 1 | B6: =IF(H6="","",1) | C6: =IF(I6="","",1) | D6: =IF(J6="","",1) -> 1 | G6: 3 | I6: =IF(ISERROR(VLOOKUP(H6,#REF!,9,0)),"",VLOOKUP(H6,#REF!,9,0)) | J6: Deassign Carrier | K6: Carrier | L6: 完成 | M6: 2022 | N6: Lot&Carrier逻辑 Divide | O6: 杨金杰
A7: =B7&D7 -> 11 | B7: =IF(H7="","",1) -> 1 | C7: =IF(I7="","",1) | D7: =IF(J7="","",1) -> 1 | G7: 4 | H7: Cancel Clean | I7: =IF(ISERROR(VLOOKUP(H7,#REF!,9,0)),"",VLOOKUP(H7,#REF!,9,0)) | J7: Cancel Clean | K7: Carrier | L7: 待确认 | M7: 2022 | N7: Cancel Set Clean,Cancel Start Clean | O7: 杨金杰
A8: =B8&D8 -> 1 | B8: =IF(H8="","",1) -> 1 | C8: =IF(I8="","",1) | D8: =IF(J8="","",1) | G8: 5 | H8: Cancel Inspection | I8: =IF(ISERROR(VLOOKUP(H8,#REF!,9,0)),"",VLOOKUP(H8,#REF!,9,0)) | K8: Carrier | L8: 未推进 | M8: 2022 | O8: 杨金杰
A9: =B9&D9 -> 11 | B9: =IF(H9="","",1) -> 1 | C9: =IF(I9="","",1) | D9: =IF(J9="","",1) -> 1 | G9: 6 | H9: Cancel Reserve Target Carrier | I9: =IF(ISERROR(VLOOKUP(H9,#REF!,9,0)),"",VLOOKUP(H9,#REF!,9,0)) | J9: Cancel Reserve Target Carrier | K9: Carrier | L9: 完成 | M9: 2022 | N9: 解绑预约Carrier,其他用途可以使用 | O9: 杨金杰
A10: =B10&D10 -> 1 | B10: =IF(H10="","",1) -> 1 | C10: =IF(I10="","",1) | D10: =IF(J10="","",1) | G10: 7 | H10: Carrier Data Collection | I10: =IF(ISERROR(VLOOKUP(H10,#REF!,9,0)),"",VLOOKUP(H10,#REF!,9,0)) | K10: Carrier | L10: 待确认 | M10: 2022 | O10: 李彬
A11: =B11&D11 -> 11 | B11: =IF(H11="","",1) -> 1 | C11: =IF(I11="","",1) | D11: =IF(J11="","",1) -> 1 | F11: Update/Modify Carrier Info | G11: 8 | H11: Change Slotmap Info | I11: =IF(ISERROR(VLOOKUP(H11,#REF!,9,0)),"",VLOOKUP(H11,#REF!,9,0)) | J11: Change Slot Map Info | K11: Carrier | L11: 完成 | M11: 2022 | N11: 改变同lot中 wafer slot信息 | O11: 杨金杰
A12: =B12&D12 -> 1 | B12: =IF(H12="","",1) | C12: =IF(I12="","",1) | D12: =IF(J12="","",1) -> 1 | G12: 9 | I12: =IF(ISERROR(VLOOKUP(H12,#REF!,9,0)),"",VLOOKUP(H12,#REF!,9,0)) | J12: Change Carrier Info | K12: Carrier | L12: 完成 | M12: 2022 | O12: 杨金杰
A13: =B13&D13 -> 11 | B13: =IF(H13="","",1) -> 1 | C13: =IF(I13="","",1) | D13: =IF(J13="","",1) -> 1 | G13: 10 | H13: Create Carrier | I13: =IF(ISERROR(VLOOKUP(H13,#REF!,9,0)),"",VLOOKUP(H13,#REF!,9,0)) | J13: Create Carrier | K13: Carrier | L13: 完成 | M13: 2022 | N13: 单个或多个Carrier创建（包括Foup.FOSB) | O13: 杨金杰
A14: =B14&D14 -> 1 | B14: =IF(H14="","",1) -> 1 | C14: =IF(I14="","",1) | D14: =IF(J14="","",1) | G14: 11 | H14: Disposal/Undo Disposal | I14: =IF(ISERROR(VLOOKUP(H14,#REF!,9,0)),"",VLOOKUP(H14,#REF!,9,0)) | K14: Carrier | L14: 未推进 | M14: 2022 | O14: 杨金杰
A15: =B15&D15 -> 11 | B15: =IF(H15="","",1) -> 1 | C15: =IF(I15="","",1) | D15: =IF(J15="","",1) -> 1 | G15: 12 | H15: Exchange Carrier | I15: =IF(ISERROR(VLOOKUP(H15,#REF!,9,0)),"",VLOOKUP(H15,#REF!,9,0)) | J15: Exchange Carrier | K15: Carrier | L15: 完成 | M15: 2022 | N15: Carrier为基准，Lot逐个传出到新的异种Foup | O15: 杨金杰
A16: =B16&D16 -> 11 | B16: =IF(H16="","",1) -> 1 | C16: =IF(I16="","",1) | D16: =IF(J16="","",1) -> 1 | G16: 13 | H16: Hold Carrier | I16: =IF(ISERROR(VLOOKUP(H16,#REF!,9,0)),"",VLOOKUP(H16,#REF!,9,0)) | J16: Hold Carrier | K16: Carrier | L16: 完成 | M16: 2022 | N16: Hold Carrier | O16: 杨金杰
A17: =B17&D17 -> 1 | B17: =IF(H17="","",1) -> 1 | C17: =IF(I17="","",1) | D17: =IF(J17="","",1) | G17: 14 | H17: Inspection Flow Control | I17: =IF(ISERROR(VLOOKUP(H17,#REF!,9,0)),"",VLOOKUP(H17,#REF!,9,0)) | K17: Carrier | L17: 未推进 | M17: 2022 | O17: 杨金杰
A18: =B18&D18 -> 11 | B18: =IF(H18="","",1) -> 1 | C18: =IF(I18="","",1) | D18: =IF(J18="","",1) -> 1 | F18: Update/Modify Carrier Info | G18: 15 | H18: Modify Carrier Attributes | I18: =IF(ISERROR(VLOOKUP(H18,#REF!,9,0)),"",VLOOKUP(H18,#REF!,9,0)) | J18: Modify Carrier Attributes | K18: Carrier | L18: 完成 | M18: 2022 | O18: 杨金杰
A19: =B19&D19 -> 1 | B19: =IF(H19="","",1) -> 1 | C19: =IF(I19="","",1) | D19: =IF(J19="","",1) | G19: 16 | H19: Start/End Inspection | I19: =IF(ISERROR(VLOOKUP(H19,#REF!,9,0)),"",VLOOKUP(H19,#REF!,9,0)) | K19: Carrier | L19: 未推进 | M19: 2022 | O19: 杨金杰
A20: =B20&D20 -> 11 | B20: =IF(H20="","",1) -> 1 | C20: =IF(I20="","",1) | D20: =IF(J20="","",1) -> 1 | G20: 17 | H20: Release Carrier | I20: =IF(ISERROR(VLOOKUP(H20,#REF!,9,0)),"",VLOOKUP(H20,#REF!,9,0)) | J20: Release Carrier | K20: Carrier | L20: 完成 | M20: 2022 | N20: 对Hold Carrier进行Release | O20: 杨金杰
A21: =B21&D21 -> 11 | B21: =IF(H21="","",1) -> 1 | C21: =IF(I21="","",1) | D21: =IF(J21="","",1) -> 1 | G21: 18 | H21: Remove Carrier | I21: =IF(ISERROR(VLOOKUP(H21,#REF!,9,0)),"",VLOOKUP(H21,#REF!,9,0)) | J21: Scrap Carrier | K21: Carrier | L21: 完成 | M21: 2022 | N21: 报废Carrier | O21: 杨金杰
A22: =B22&D22 -> 1 | B22: =IF(H22="","",1) -> 1 | C22: =IF(I22="","",1) | D22: =IF(J22="","",1) | G22: 19 | H22: Repair FOUP | I22: =IF(ISERROR(VLOOKUP(H22,#REF!,9,0)),"",VLOOKUP(H22,#REF!,9,0)) | K22: Carrier | L22: 未推进 | M22: 2022 | O22: 杨金杰
A23: =B23&D23 -> 11 | B23: =IF(H23="","",1) -> 1 | C23: =IF(I23="","",1) | D23: =IF(J23="","",1) -> 1 | G23: 20 | H23: Reserve Target Carrier | I23: =IF(ISERROR(VLOOKUP(H23,#REF!,9,0)),"",VLOOKUP(H23,#REF!,9,0)) | J23: Reserve Target Carrier | K23: Carrier | L23: 开发中 | M23: 2022 | N23: 预约Carrier,防止其他用途使用 | O23: 杨金杰
A24: =B24&D24 -> 1 | B24: =IF(H24="","",1) -> 1 | C24: =IF(I24="","",1) | D24: =IF(J24="","",1) | G24: 21 | H24: Set Disposal/Cancel Disposal | I24: =IF(ISERROR(VLOOKUP(H24,#REF!,9,0)),"",VLOOKUP(H24,#REF!,9,0)) | K24: Carrier | L24: 未推进 | M24: 2022 | O24: 杨金杰
A25: =B25&D25 -> 1 | B25: =IF(H25="","",1) | C25: =IF(I25="","",1) | D25: =IF(J25="","",1) -> 1 | G25: 22 | I25: =IF(ISERROR(VLOOKUP(H25,#REF!,9,0)),"",VLOOKUP(H25,#REF!,9,0)) | J25: Cancel Scrap Carrier | K25: Carrier | L25: 完成 | M25: 2022 | N25: 解除报废Carrier | O25: 杨金杰
A26: =B26&D26 -> 1 | B26: =IF(H26="","",1) | C26: =IF(I26="","",1) | D26: =IF(J26="","",1) -> 1 | G26: 23 | I26: =IF(ISERROR(VLOOKUP(H26,#REF!,9,0)),"",VLOOKUP(H26,#REF!,9,0)) | J26: Change Carrier Clean State | K26: Carrier | L26: 完成 | M26: 2022 | O26: 杨金杰
A27: =B27&D27 -> 1 | B27: =IF(H27="","",1) | C27: =IF(I27="","",1) | D27: =IF(J27="","",1) -> 1 | G27: 24 | I27: =IF(ISERROR(VLOOKUP(H27,#REF!,9,0)),"",VLOOKUP(H27,#REF!,9,0)) | J27: Carrier RFID Management | K27: Carrier | L27: 完成 | M27: 2022 | O27: 杨金杰
A28: =B28&D28 -> 11 | B28: =IF(H28="","",1) -> 1 | C28: =IF(I28="","",1) | D28: =IF(J28="","",1) -> 1 | G28: 25 | H28: Set Clean | I28: =IF(ISERROR(VLOOKUP(H28,#REF!,9,0)),"",VLOOKUP(H28,#REF!,9,0)) | J28: Set Clean | K28: Carrier | L28: 待确认 | M28: 2022 | O28: 杨金杰
A29: =B29&D29 -> 1 | B29: =IF(H29="","",1) -> 1 | C29: =IF(I29="","",1) | D29: =IF(J29="","",1) | G29: 26 | H29: Set Inspection | I29: =IF(ISERROR(VLOOKUP(H29,#REF!,9,0)),"",VLOOKUP(H29,#REF!,9,0)) | K29: Carrier | L29: 未推进 | M29: 2022 | O29: 杨金杰
A30: =B30&D30 -> 1 | B30: =IF(H30="","",1) -> 1 | C30: =IF(I30="","",1) | D30: =IF(J30="","",1) | G30: 27 | H30: Special Transfer Lot | I30: =IF(ISERROR(VLOOKUP(H30,#REF!,9,0)),"",VLOOKUP(H30,#REF!,9,0)) | K30: Carrier | L30: 未推进 | M30: 2022 | O30: 杨金杰
A31: =B31&D31 -> 11 | B31: =IF(H31="","",1) -> 1 | C31: =IF(I31="","",1) | D31: =IF(J31="","",1) -> 1 | G31: 28 | H31: Start/End Clean | I31: =IF(ISERROR(VLOOKUP(H31,#REF!,9,0)),"",VLOOKUP(H31,#REF!,9,0)) | J31: Start/End Clean | K31: Carrier | L31: 待确认 | M31: 2022 | O31: 杨金杰
A32: =B32&D32 -> 11 | B32: =IF(H32="","",1) -> 1 | C32: =IF(I32="","",1) | D32: =IF(J32="","",1) -> 1 | G32: 29 | H32: Transfer Lot | I32: =IF(ISERROR(VLOOKUP(H32,#REF!,9,0)),"",VLOOKUP(H32,#REF!,9,0)) | J32: Transfer Lot | K32: Carrier | L32: 完成 | M32: 2022 | N32: Lot Base 传到其他同类型Foup | O32: 杨金杰
A33: =B33&D33 -> 1 | B33: =IF(H33="","",1) -> 1 | C33: =IF(I33="","",1) | D33: =IF(J33="","",1) | G33: 30 | H33: Update Carrier Component | I33: =IF(ISERROR(VLOOKUP(H33,#REF!,9,0)),"",VLOOKUP(H33,#REF!,9,0)) | K33: Carrier | L33: 未推进 | M33: 2022 | O33: 杨金杰
A34: =B34&D34 -> 1 | B34: =IF(H34="","",1) | C34: =IF(I34="","",1) | D34: =IF(J34="","",1) -> 1 | G34: 31 | I34: =IF(ISERROR(VLOOKUP(H34,#REF!,9,0)),"",VLOOKUP(H34,#REF!,9,0)) | J34: View Carrier List | K34: Carrier | L34: 完成 | M34: 2022 | O34: 杨金杰
A35: =B35&D35 -> 1 | B35: =IF(H35="","",1) -> 1 | C35: =IF(I35="","",1) | D35: =IF(J35="","",1) | F35: View Carrier Info | G35: 32 | H35: View Carrier Cleaning History | I35: =IF(ISERROR(VLOOKUP(H35,#REF!,9,0)),"",VLOOKUP(H35,#REF!,9,0)) | K35: Carrier | L35: 未推进 | M35: 2022 | O35: 杨金杰
A36: =B36&D36 -> 1 | B36: =IF(H36="","",1) -> 1 | C36: =IF(I36="","",1) | D36: =IF(J36="","",1) | F36: View Carrier Info | G36: 33 | H36: View Carrier Cycle | I36: =IF(ISERROR(VLOOKUP(H36,#REF!,9,0)),"",VLOOKUP(H36,#REF!,9,0)) | K36: Carrier | L36: 未推进 | M36: 2022 | O36: 杨金杰
A37: =B37&D37 -> 11 | B37: =IF(H37="","",1) -> 1 | C37: =IF(I37="","",1) | D37: =IF(J37="","",1) -> 1 | F37: View Carrier Info | G37: 34 | H37: View Carrier History | I37: =IF(ISERROR(VLOOKUP(H37,#REF!,9,0)),"",VLOOKUP(H37,#REF!,9,0)) | J37: View Carrier History | K37: Carrier | L37: 完成 | M37: 2022 | N37: 查询Carrier的Detail 历史记录 | O37: 杨金杰
A38: =B38&D38 -> 11 | B38: =IF(H38="","",1) -> 1 | C38: =IF(I38="","",1) | D38: =IF(J38="","",1) -> 1 | F38: View Carrier Info | G38: 35 | H38: View Carrier Status | I38: =IF(ISERROR(VLOOKUP(H38,#REF!,9,0)),"",VLOOKUP(H38,#REF!,9,0)) | J38: View Carrier Status | K38: Carrier | L38: 完成 | M38: 2022 | N38: 查询Carrier 当前状态 | O38: 杨金杰
A39: =B39&D39 -> 1 | B39: =IF(H39="","",1) -> 1 | C39: =IF(I39="","",1) | D39: =IF(J39="","",1) | E39: Eqp Mgt | G39: 36 | H39: Buffer Tool Physical Foup Maintain | I39: =IF(ISERROR(VLOOKUP(H39,#REF!,9,0)),"",VLOOKUP(H39,#REF!,9,0)) | K39: Machine | L39: 未推进 | M39: 2022 | O39: 杨金杰
A40: =B40&D40 -> 1 | B40: =IF(H40="","",1) -> 1 | C40: =IF(I40="","",1) | D40: =IF(J40="","",1) | F40: One Key Touch | G40: 37 | H40: Control Action History | I40: =IF(ISERROR(VLOOKUP(H40,#REF!,9,0)),"",VLOOKUP(H40,#REF!,9,0)) | K40: Machine | L40: 未推进 | M40: 2022 | O40: 杨金杰
A41: =B41&D41 -> 1 | B41: =IF(H41="","",1) -> 1 | C41: =IF(I41="","",1) | D41: =IF(J41="","",1) | G41: 38 | H41: Customize EQP Information | I41: =IF(ISERROR(VLOOKUP(H41,#REF!,9,0)),"",VLOOKUP(H41,#REF!,9,0)) | K41: Machine | L41: 未推进 | M41: 2022 | O41: 杨金杰
...

Sheet cvMES
A1: 一级名字 | B1: 二级名字 | C1: 三级名字
A2: WIP | B2: Plan | C2: Product Order
A3: WIP | B3: Plan | C3: Work Order
A4: WIP | B4: Plan | C4: View PO/WO History
A5: WIP | B5: Plan | C5: Create Lot
A6: WIP | B6: Plan | C6: Create NPW Lot
A7: WIP | B7: Plan | C7: Create Engineer Lot
A8: WIP | B8: Plan | C8: View Create Lot List
A9: WIP | B9: Source Lot | C9: View Transaction Raw Wafer List
A10: WIP | B10: Source Lot | C10: View Raw Wafer List
A11: WIP | B11: Source Lot | C11: FOSB Generate
A12: WIP | B12: Source Lot | C12: Create Source Vendor Lot
... A232: Inquiry | B232: NPW | C232: View Furnace Batch History

Sheet raw
A1: 序号 | B1: 一级模块 | C1: 二级模块 | D1: 三级模块(Function Name) | E1: UI | F1: Access String Full Name
A2: 1 | B2: Main | C2: Main | D2: Main WIP | E2: #N/A | F2: Update Recipe:弹出Update Recipe框
A3: 15 | D3: PHOTO WIP | E3: #N/A | F3: Search：通过条件查询ProcessOperationList数据
A4: 16 | E4: #N/A | F4: Scanner Queue Add:新增Scanner Q
A5: 17 | E5: #N/A | F5: Scanner Queue Delete:删除Scanner Q
A6: 18 | E6: #N/A | F6: check：移动后保存RunLotList的Lot顺序
A7: 19 | E7: #N/A | F7: Pause Add:阻止Scanner Q生成
A8: 20 | E8: #N/A | F8: Pause Delete:删除阻止Scanner Q生成
A9: 21 | E9: #N/A | F9: Track Recipe:选择TrackRecipe
A10: 22 | E10: #N/A | F10: Scanner Recipe:选择ScannerRecipe
A11: 28 | D11: Sorter WIP | E11: #N/A
A12: 45 | D12: WIP UI(Lot View) | E12: #N/A
A13: 55 | B13: WIP | C13: Plan | D13: Product Order | E13: #N/A | F13: Create:创建Product Order
A14: 56 | E14: #N/A | F14: Remove:删除Product Order
A15: 57 | E15: #N/A | F15: Modify :修改Produt Order
A16: 58 | D16: Work Order | E16: #N/A | F16: Create:创建Work Order
A17: 59 | E17: #N/A | F17: Remove:删除Work Order
A18: 60 | E18: #N/A | F18: Modify :修改Work Order
A19: 61 | D19: View PO/WO History | E19: View PO/WO History | F19: History：查看History
A20: 62 | D20: Create Lot | E20: Create Lot | F20: Confirm：确认生成Lot Name
A21: 63 | D21: Create NPW Lot | E21: Create NPW Lot | F21: Confirm：确认生成Lot Name
A22: 64 | D22: Create Engineer Lot | E22: Create Engineer Lot | F22: Confirm：确认生成Lot Name
A23: 65 | D23: View Create Lot List | E23: View Create Lot List | F23: Modify：对Lot 的Plan Data 编辑进行保存
A24: 66 | E24: #N/A | F24: Cancel：删除已生成的Lot Name
A25: 67 | E25: #N/A | F25: Release : 针对qty<create qty的lot强制Release
A26: 68 | C26: Source Lot | D26: View Transaction Raw Wafer List | E26: View Transaction Raw Wafer List | F26: Confirm：接收Raw Wafer
A27: 69 | D27: View Raw Wafer List | E27: View Raw Wafer List | F27: History：查看History
A28: 70 | D28: Create Source Vendor Lot | E28: Create Source Vendor Lot | F28: Confirm：生成Source Vendor Lot
A29: 71 | D29: View Source Vendor Lot List | E29: #N/A | F29: Search
A30: 72 | C30: Wafer Start | D30: Start Lot | E30: Start Lot | F30: Confirm：manual start lot
A31: 73 | D31: Start Lot(PDA) | E31: #N/A | F31: Confirm：使用PDA start lot
A32: 74 | D32: Insert T7 Code | E32: Insert T7 Code | F32: Confirm：对T7 Code 进行手动编辑
A33: 75 | D33: Start Lot (Auto) | E33: #N/A | F33: Confirm：Auto start lot
A34: 76 | D34: Wafer Start Reserve | E34: Wafer Start Reserve | F34: Confirm：fast track in
A35: 77 | D35: Zero Layer Wafer Start | E35: #N/A | F35: Confirm
A36: 78 | D36: View Start Lot | E36: View Start Lot | F36: Cancel Reserve：取消Sorter 操作
A37: 79 | E37: #N/A | F37: Manual Track Out
A38: 80 | D38: Skip Started Lot | E38: Skip Started Lot | F38: Skip：从虚拟栈点skip 到实际第一栈
A39: 81 | D39: Input Plan Report | E39: #N/A
A40: 82 | C40: Tracking | D40: Prepare Lot | E40: Prepare Lot | F40: WaferSelect:量测lot选择wafer
...
